<?xml version="1.0" ?>
<robot name="hyrian" xmlns:xacro="http://www.ros.org/wiki/xacro">

<xacro:include filename="$(find hyrian_description)/urdf/materials.xacro" />
<xacro:include filename="$(find hyrian_description)/urdf/hyrian.trans" />
<xacro:include filename="$(find hyrian_description)/urdf/hyrian.gazebo" />
<link name="base_link">
  <inertial>
    <origin xyz="-0.10669076554678224 1.5621095382552616e-06 0.12074565974295158" rpy="0 0 0"/>
    <mass value="58.74508266414039"/>
    <inertia ixx="0.436723" iyy="0.452655" izz="0.565557" ixy="0.001014" iyz="-9e-06" ixz="-0.007055"/>
  </inertial>
  <visual>
    <origin xyz="0 0 0" rpy="0 0 0"/>
    <geometry>
      <mesh filename="file://$(find hyrian_description)/meshes/base_link.stl" scale="0.001 0.001 0.001"/>
    </geometry>
    <material name="silver"/>
  </visual>
  <collision>
    <origin xyz="0 0 0" rpy="0 0 0"/>
    <geometry>
      <mesh filename="file://$(find hyrian_description)/meshes/base_link.stl" scale="0.001 0.001 0.001"/>
    </geometry>
  </collision>
</link>

<link name="caster_1">
  <inertial>
    <origin xyz="-0.017519805982381953 4.3013561084737665e-08 -0.05240102727593725" rpy="0 0 0"/>
    <mass value="1.6117880362991714"/>
    <inertia ixx="0.001424" iyy="0.001841" izz="0.000923" ixy="-0.0" iyz="0.0" ixz="-0.000298"/>
  </inertial>
  <visual>
    <origin xyz="0.279 -0.0 -0.043" rpy="0 0 0"/>
    <geometry>
      <mesh filename="file://$(find hyrian_description)/meshes/caster_1.stl" scale="0.001 0.001 0.001"/>
    </geometry>
    <material name="silver"/>
  </visual>
  <collision>
    <origin xyz="0.279 -0.0 -0.043" rpy="0 0 0"/>
    <geometry>
      <mesh filename="file://$(find hyrian_description)/meshes/caster_1.stl" scale="0.001 0.001 0.001"/>
    </geometry>
  </collision>
</link>

<link name="lidar_1">
  <inertial>
    <origin xyz="2.5778920109686965e-09 6.0217946361192236e-18 0.023813967631461597" rpy="0 0 0"/>
    <mass value="1.482019447760714"/>
    <inertia ixx="0.000761" iyy="0.000761" izz="0.000958" ixy="0.0" iyz="0.0" ixz="0.0"/>
  </inertial>
  <visual>
    <origin xyz="-0.068 0.0 -0.049" rpy="0 0 0"/>
    <geometry>
      <mesh filename="file://$(find hyrian_description)/meshes/lidar_1.stl" scale="0.001 0.001 0.001"/>
    </geometry>
    <material name="silver"/>
  </visual>
  <collision>
    <origin xyz="-0.068 0.0 -0.049" rpy="0 0 0"/>
    <geometry>
      <mesh filename="file://$(find hyrian_description)/meshes/lidar_1.stl" scale="0.001 0.001 0.001"/>
    </geometry>
  </collision>
</link>

<link name="right_wheel_1">
  <inertial>
    <origin xyz="4.192763186755608e-09 0.006200869145559784 1.995829389735125e-09" rpy="0 0 0"/>
    <mass value="1.326090407403013"/>
    <inertia ixx="0.001415" iyy="0.002676" izz="0.001415" ixy="0.0" iyz="0.0" ixz="0.0"/>
  </inertial>
  <visual>
    <origin xyz="-0.0 0.2118 0.0" rpy="0 0 0"/>
    <geometry>
      <mesh filename="file://$(find hyrian_description)/meshes/right_wheel_1.stl" scale="0.001 0.001 0.001"/>
    </geometry>
    <material name="silver"/>
  </visual>
  <collision>
    <origin xyz="-0.0 0.2118 0.0" rpy="0 0 0"/>
    <geometry>
      <mesh filename="file://$(find hyrian_description)/meshes/right_wheel_1.stl" scale="0.001 0.001 0.001"/>
    </geometry>
  </collision>
</link>

<link name="left_wheel_1">
  <inertial>
    <origin xyz="4.192763026999893e-09 -0.006200869145558702 -1.995829641831094e-09" rpy="0 0 0"/>
    <mass value="1.3260904074030184"/>
    <inertia ixx="0.001415" iyy="0.002676" izz="0.001415" ixy="-0.0" iyz="0.0" ixz="-0.0"/>
  </inertial>
  <visual>
    <origin xyz="-0.0 -0.2118 0.0" rpy="0 0 0"/>
    <geometry>
      <mesh filename="file://$(find hyrian_description)/meshes/left_wheel_1.stl" scale="0.001 0.001 0.001"/>
    </geometry>
    <material name="silver"/>
  </visual>
  <collision>
    <origin xyz="-0.0 -0.2118 0.0" rpy="0 0 0"/>
    <geometry>
      <mesh filename="file://$(find hyrian_description)/meshes/left_wheel_1.stl" scale="0.001 0.001 0.001"/>
    </geometry>
  </collision>
</link>

<joint name="��ü 15" type="fixed">
  <origin xyz="-0.279 0.0 0.043" rpy="0 0 0"/>
  <parent link="base_link"/>
  <child link="caster_1"/>
</joint>

<joint name="��ü 13" type="fixed">
  <origin xyz="0.068 0.0 0.049" rpy="0 0 0"/>
  <parent link="base_link"/>
  <child link="lidar_1"/>
</joint>

<joint name="right_wheel_joint" type="continuous">
  <origin xyz="0.0 -0.2118 0.0" rpy="0 0 0"/>
  <parent link="base_link"/>
  <child link="right_wheel_1"/>
  <axis xyz="0.0 -1.0 0.0"/>
</joint>

<joint name="left_wheel_joint" type="continuous">
  <origin xyz="0.0 0.2118 0.0" rpy="0 0 0"/>
  <parent link="base_link"/>
  <child link="left_wheel_1"/>
  <axis xyz="-0.0 1.0 -0.0"/>
</joint>

<gazebo>
    <plugin filename="libgazebo_ros2_control.so" name="gazebo_ros2_control">
       <robot_param>robot_description</robot_param>
      <robot_param_node>robot_state_publisher</robot_param_node>
      <parameters>$(find hyrian_bringup)/config/controllers.yaml</parameters>
    </plugin>
</gazebo>
</robot>
