<?xml version="1.0" ?>
<robot name="hyrian" xmlns:xacro="http://www.ros.org/wiki/xacro">

<xacro:include filename="$(find hyrian_description)/urdf/materials.xacro" />
<!-- <xacro:include filename="$(find hyrian_description)/urdf/hyrian.trans" />
<xacro:include filename="$(find hyrian_description)/urdf/hyrian.gazebo" /> -->

<link name="base_footprint"/>

<joint name="base_joint" type="fixed">
  <parent link="base_footprint"/>
  <child link="base_link" />
  <origin xyz="0 0 0 " rpy="0 0 0.0"/>
</joint>


<link name="base_link">
  <inertial>
    <origin xyz="-0.10227978369059341 1.1257994758378733e-05 0.4082809761720818" rpy="0 0 0"/>
    <mass value="50.58143073299084"/>
    <inertia ixx="19.58631" iyy="19.219571" izz="3.81789" ixy="-0.002995" iyz="0.011725" ixz="-0.581839"/>
  </inertial>
  <visual>
    <origin xyz="0 0 0" rpy="0 0 0"/>
    <geometry>
      <mesh filename="file://$(find hyrian_description)/meshes/base_link.stl" scale="0.001 0.001 0.001"/>
    </geometry>
    <material name="silver"/>
  </visual>
  <collision>
    <origin xyz="0 0 0" rpy="0 0 0"/>
    <geometry>
      <mesh filename="file://$(find hyrian_description)/meshes/base_link.stl" scale="0.001 0.001 0.001"/>
    </geometry>
  </collision>
</link>

<link name="left_wheel_1">
  <inertial>
    <origin xyz="-2.3734552044097149e-07 -0.002797911787755736 7.297815416647854e-08" rpy="0 0 0"/>
    <mass value="0.1571644899281903"/>
    <inertia ixx="0.000168" iyy="0.000317" izz="0.000168" ixy="0.0" iyz="0.0" ixz="-0.0"/>
  </inertial>
  <visual>
    <origin xyz="-0.000223 -0.208786 -8.1e-05" rpy="0 0 0"/>
    <geometry>
      <mesh filename="file://$(find hyrian_description)/meshes/left_wheel_1.stl" scale="0.001 0.001 0.001"/>
    </geometry>
    <material name="silver"/>
  </visual>
  <collision>
    <origin xyz="-0.000223 -0.208786 -8.1e-05" rpy="0 0 0"/>
    <geometry>
      <mesh filename="file://$(find hyrian_description)/meshes/left_wheel_1.stl" scale="0.001 0.001 0.001"/>
    </geometry>
  </collision>
</link>

<joint name="left_wheel_joint" type="continuous">
  <origin xyz="0.000223 0.208786 8.1e-05" rpy="0 0 0"/>
  <parent link="base_link"/>
  <child link="left_wheel_1"/>
  <axis xyz="0.0 1.0 0.0"/>
</joint>

<link name="right_wheel_1">
  <inertial>
    <origin xyz="-2.3698372196977071e-07 0.0027981825588338505 7.261635420341558e-08" rpy="0 0 0"/>
    <mass value="0.15716448992819132"/>
    <inertia ixx="0.000168" iyy="0.000317" izz="0.000168" ixy="-0.0" iyz="-0.0" ixz="-0.0"/>
  </inertial>
  <visual>
    <origin xyz="-0.000223 0.208014 -8.1e-05" rpy="0 0 0"/>
    <geometry>
      <mesh filename="file://$(find hyrian_description)/meshes/right_wheel_1.stl" scale="0.001 0.001 0.001"/>
    </geometry>
    <material name="silver"/>
  </visual>
  <collision>
    <origin xyz="-0.000223 0.208014 -8.1e-05" rpy="0 0 0"/>
    <geometry>
      <mesh filename="file://$(find hyrian_description)/meshes/right_wheel_1.stl" scale="0.001 0.001 0.001"/>
    </geometry>
  </collision>
</link>

<joint name="right_wheel_joint" type="continuous">
  <origin xyz="0.000223 -0.208014 8.1e-05" rpy="0 0 0"/>
  <parent link="base_link"/>
  <child link="right_wheel_1"/>
  <axis xyz="0.0 1.0 0.0"/>
</joint>

<link name="laser_frame">
  <inertial>
    <origin xyz="-2.360620741659325e-07 -5.8259209553173166e-08 0.01758209864836971" rpy="0 0 0"/>
    <mass value="0.5963952762384188"/>
    <inertia ixx="0.000193" iyy="0.000193" izz="0.00034" ixy="0.0" iyz="-0.0" ixz="-0.0"/>
  </inertial>
  <visual>
    <origin xyz="-0.065223 -0.000386 -0.071081" rpy="0 0 0"/>
    <geometry>
      <mesh filename="file://$(find hyrian_description)/meshes/lidar_1.stl" scale="0.001 0.001 0.001"/>
    </geometry>
    <material name="silver"/>
  </visual>
  <collision>
    <origin xyz="-0.065223 -0.000386 -0.071081" rpy="0 0 0"/>
    <geometry>
      <mesh filename="file://$(find hyrian_description)/meshes/lidar_1.stl" scale="0.001 0.001 0.001"/>
    </geometry>
  </collision>
</link>

<joint name="lidar_joint" type="fixed">
  <origin xyz="0.065223 0.000386 0.071081" rpy="0 0 0"/>
  <parent link="base_link"/>
  <child link="laser_frame"/>
</joint>

<joint name="imu_joint" type="fixed">
  <parent link="base_link"/>
  <child link="imu_link"/>
  <origin xyz="0.0 0.0 0.2" rpy="0 0 0"/>
</joint>

<link name="imu_link"/>

<link name="caster_wheel_1">
  <inertial>
    <origin xyz="-3.774694260494371e-07 0.02649994085654633 3.6178873507805576e-07" rpy="0 0 0"/>
    <mass value="0.30017628607414365"/>
    <inertia ixx="0.000146" iyy="0.000231" izz="0.000146" ixy="0.0" iyz="0.0" ixz="0.0"/>
  </inertial>
  <visual>
    <origin xyz="0.281078 0.026114 0.018871" rpy="0 0 0"/>
    <geometry>
      <mesh filename="file://$(find hyrian_description)/meshes/caster_wheel_1.stl" scale="0.001 0.001 0.001"/>
    </geometry>
    <material name="silver"/>
  </visual>
  <collision>
    <origin xyz="0.281078 0.026114 0.018871" rpy="0 0 0"/>
    <geometry>
      <mesh filename="file://$(find hyrian_description)/meshes/caster_wheel_1.stl" scale="0.001 0.001 0.001"/>
    </geometry>
  </collision>
</link>

<link name="caster_1">
  <inertial>
    <origin xyz="-0.00016533499198501111 -3.5359387945718625e-05 -0.019350707153866404" rpy="0 0 0"/>
    <mass value="0.2826691939173363"/>
    <inertia ixx="0.000229" iyy="0.000138" izz="0.000165" ixy="-0.0" iyz="-0.0" ixz="-2e-06"/>
  </inertial>
  <visual>
    <origin xyz="0.281777 -0.000386 -0.027081" rpy="0 0 0"/>
    <geometry>
      <mesh filename="file://$(find hyrian_description)/meshes/caster_1.stl" scale="0.001 0.001 0.001"/>
    </geometry>
    <material name="silver"/>
  </visual>
  <collision>
    <origin xyz="0.281777 -0.000386 -0.027081" rpy="0 0 0"/>
    <geometry>
      <mesh filename="file://$(find hyrian_description)/meshes/caster_1.stl" scale="0.001 0.001 0.001"/>
    </geometry>
  </collision>
</link>



<joint name="°­Ã¼ 37" type="fixed">
  <origin xyz="0.000699 -0.0265 -0.045952" rpy="0 0 0"/>
  <parent link="caster_1"/>
  <child link="caster_wheel_1"/>
</joint>

<joint name="°­Ã¼ 38" type="fixed">
  <origin xyz="-0.281777 0.000386 0.027081" rpy="0 0 0"/>
  <parent link="base_link"/>
  <child link="caster_1"/>
</joint>
</robot>
